<?xml version="1.0" ?>
<!-- =================================================================================== -->
<!-- |    This document was autogenerated by xacro from robotic_arm_description/urdf/robotic_arm_kdl.xacro | -->
<!-- |    EDITING THIS FILE BY HAND IS NOT RECOMMENDED                                 | -->
<!-- =================================================================================== -->
<robot name="robotic_arm">
  <material name="silver_default">
    <color rgba="0.700 0.700 0.700 1.000"/>
  </material>
  <material name="oak">
    <color rgba="0.7098 0.5882 0.4431 1.000"/>
  </material>
  <material name="pa_12_nylon_pa_603cf_with_eos_p_3d_printers">
    <color rgba="0.24705882352941178 0.24705882352941178 0.24705882352941178 1.0"/>
  </material>
  <transmission name="base_waist_joint_tran">
    <type>transmission_interface/SimpleTransmission</type>
    <joint name="base_waist_joint">
      <hardwareInterface>hardware_interface/EffortJointInterface</hardwareInterface>
    </joint>
    <actuator name="base_waist_joint_actr">
      <hardwareInterface>hardware_interface/EffortJointInterface</hardwareInterface>
      <mechanicalReduction>1</mechanicalReduction>
    </actuator>
  </transmission>
  <transmission name="waist_link1_joint_tran">
    <type>transmission_interface/SimpleTransmission</type>
    <joint name="waist_link1_joint">
      <hardwareInterface>hardware_interface/EffortJointInterface</hardwareInterface>
    </joint>
    <actuator name="waist_link1_joint_actr">
      <hardwareInterface>hardware_interface/EffortJointInterface</hardwareInterface>
      <mechanicalReduction>1</mechanicalReduction>
    </actuator>
  </transmission>
  <transmission name="link1_link2_joint_tran">
    <type>transmission_interface/SimpleTransmission</type>
    <joint name="link1_link2_joint">
      <hardwareInterface>hardware_interface/EffortJointInterface</hardwareInterface>
    </joint>
    <actuator name="link1_link2_joint_actr">
      <hardwareInterface>hardware_interface/EffortJointInterface</hardwareInterface>
      <mechanicalReduction>1</mechanicalReduction>
    </actuator>
  </transmission>
  <transmission name="link2_gripper_base_joint_tran">
    <type>transmission_interface/SimpleTransmission</type>
    <joint name="link2_gripper_base_joint">
      <hardwareInterface>hardware_interface/EffortJointInterface</hardwareInterface>
    </joint>
    <actuator name="link2_gripper_base_joint_actr">
      <hardwareInterface>hardware_interface/EffortJointInterface</hardwareInterface>
      <mechanicalReduction>1</mechanicalReduction>
    </actuator>
  </transmission>
  <transmission name="left_gripper_joint_tran">
    <type>transmission_interface/SimpleTransmission</type>
    <joint name="left_gripper_joint">
      <hardwareInterface>hardware_interface/EffortJointInterface</hardwareInterface>
    </joint>
    <actuator name="left_gripper_joint_actr">
      <hardwareInterface>hardware_interface/EffortJointInterface</hardwareInterface>
      <mechanicalReduction>1</mechanicalReduction>
    </actuator>
  </transmission>
  <transmission name="right_gripper_joint_tran">
    <type>transmission_interface/SimpleTransmission</type>
    <joint name="right_gripper_joint">
      <hardwareInterface>hardware_interface/EffortJointInterface</hardwareInterface>
    </joint>
    <actuator name="right_gripper_joint_actr">
      <hardwareInterface>hardware_interface/EffortJointInterface</hardwareInterface>
      <mechanicalReduction>1</mechanicalReduction>
    </actuator>
  </transmission>
  <gazebo>
    <plugin filename="libgazebo_ros2_control.so" name="gazebo_ros2_control">
      <robot_param> robot_description</robot_param>
      <robot_param_node> robot_state_publisher</robot_param_node>
      <parameters>/home/kevo/ros_ws/src/ai_based_sorting_robot_arm/install/robotic_arm_controllers/share/robotic_arm_controllers/config/robot_arm_controllers.yaml</parameters>
    </plugin>
  </gazebo>
  <gazebo reference="base_link">
    <material>Gazebo/Oak</material>
    <mu1>0.2</mu1>
    <mu2>0.2</mu2>
    <self_collide>true</self_collide>
    <gravity>true</gravity>
  </gazebo>
  <gazebo reference="base">
    <material>Gazebo/FlatBlack</material>
    <mu1>0.2</mu1>
    <mu2>0.2</mu2>
    <self_collide>true</self_collide>
  </gazebo>
  <gazebo reference="waist">
    <material>Gazebo/FlatBlack</material>
    <mu1>0.2</mu1>
    <mu2>0.2</mu2>
    <self_collide>true</self_collide>
  </gazebo>
  <gazebo reference="link_1">
    <material>Gazebo/FlatBlack</material>
    <mu1>0.2</mu1>
    <mu2>0.2</mu2>
    <self_collide>true</self_collide>
  </gazebo>
  <gazebo reference="link_2">
    <material>Gazebo/FlatBlack</material>
    <mu1>0.2</mu1>
    <mu2>0.2</mu2>
    <self_collide>true</self_collide>
  </gazebo>
  <gazebo reference="gripper_base">
    <material>Gazebo/FlatBlack</material>
    <mu1>0.2</mu1>
    <mu2>0.2</mu2>
    <self_collide>true</self_collide>
  </gazebo>
  <gazebo reference="gripper_finger_1">
    <material>Gazebo/Blue</material>
    <mu1>0.2</mu1>
    <mu2>0.2</mu2>
    <self_collide>true</self_collide>
  </gazebo>
  <gazebo reference="gripper_finger_2">
    <material>Gazebo/Blue</material>
    <mu1>0.2</mu1>
    <mu2>0.2</mu2>
    <self_collide>true</self_collide>
  </gazebo>
  <!-- Space btw top of beam and the each joint -->
  <!-- Links -->
  <link name="world"/>
  <link name="base_link">
    <inertial>
      <origin rpy="0 0 0" xyz="4.1292719567255465e-17 -0.1275 0.0075"/>
      <mass value="2.5408670074548567"/>
      <inertia ixx="0.033061" ixy="-0.0" ixz="0.0" iyy="0.074955" iyz="0.0" izz="0.107921"/>
    </inertial>
    <visual>
      <origin rpy="0 0 0" xyz="0 0 0"/>
      <geometry>
        <mesh filename="package://robotic_arm_description/meshes/base_link.stl" scale="0.001 0.001 0.001"/>
      </geometry>
      <material name="oak"/>
    </visual>
    <collision>
      <origin rpy="0 0 0" xyz="0 0 0"/>
      <geometry>
        <mesh filename="package://robotic_arm_description/meshes/base_link.stl" scale="0.001 0.001 0.001"/>
      </geometry>
    </collision>
  </link>
  <link name="base">
    <inertial>
      <origin rpy="0 0 0" xyz="3.3070895591155684e-07 -0.06999939486232219 0.051365620594267386"/>
      <mass value="0.5102582987586253"/>
      <inertia ixx="0.001541" ixy="0.0" ixz="0.0" iyy="0.00162" iyz="0.0" izz="0.002267"/>
    </inertial>
    <visual>
      <origin rpy="0 0 0" xyz="-0.0 -0.07 -0.015"/>
      <geometry>
        <mesh filename="package://robotic_arm_description/meshes/base.stl" scale="0.001 0.001 0.001"/>
      </geometry>
      <material name="pa_12_nylon_pa_603cf_with_eos_p_3d_printers"/>
    </visual>
    <collision>
      <origin rpy="0 0 0" xyz="-0.0 -0.07 -0.015"/>
      <geometry>
        <mesh filename="package://robotic_arm_description/meshes/base.stl" scale="0.001 0.001 0.001"/>
      </geometry>
    </collision>
  </link>
  <link name="waist">
    <inertial>
      <origin rpy="0 0 0" xyz="-0.013899791072812253 -0.003284120079222943 0.02372142968591144"/>
      <mass value="0.11734363935702768"/>
      <inertia ixx="8.6e-05" ixy="-3e-06" ixz="1.4e-05" iyy="7.9e-05" iyz="1.1e-05" izz="8.5e-05"/>
    </inertial>
    <visual>
      <origin rpy="0 0 0" xyz="0.0 0.0 -0.101"/>
      <geometry>
        <mesh filename="package://robotic_arm_description/meshes/waist.stl" scale="0.001 0.001 0.001"/>
      </geometry>
      <material name="pa_12_nylon_pa_603cf_with_eos_p_3d_printers"/>
    </visual>
    <collision>
      <origin rpy="0 0 0" xyz="0.0 0.0 -0.101"/>
      <geometry>
        <mesh filename="package://robotic_arm_description/meshes/waist.stl" scale="0.001 0.001 0.001"/>
      </geometry>
    </collision>
  </link>
  <link name="link_1">
    <inertial>
      <origin rpy="0 0 0" xyz="0.007817729878361625 -4.0523557253042963e-07 0.06000021649587692"/>
      <mass value="0.07112302510728019"/>
      <inertia ixx="0.000121" ixy="0.0" ixz="0.0" iyy="0.000116" iyz="-0.0" izz="1e-05"/>
    </inertial>
    <visual>
      <origin rpy="0 0 0" xyz="0.001 0.014069 -0.141262"/>
      <geometry>
        <mesh filename="package://robotic_arm_description/meshes/link_1.stl" scale="0.001 0.001 0.001"/>
      </geometry>
      <material name="pa_12_nylon_pa_603cf_with_eos_p_3d_printers"/>
    </visual>
    <collision>
      <origin rpy="0 0 0" xyz="0.001 0.014069 -0.141262"/>
      <geometry>
        <mesh filename="package://robotic_arm_description/meshes/link_1.stl" scale="0.001 0.001 0.001"/>
      </geometry>
    </collision>
  </link>
  <link name="link_2">
    <inertial>
      <origin rpy="0 0 0" xyz="-0.01594540180295605 -0.046193837589282 4.672518474457821e-05"/>
      <mass value="0.11456681455688399"/>
      <inertia ixx="0.000224" ixy="2.7e-05" ixz="-0.0" iyy="2.7e-05" iyz="0.0" izz="0.00023"/>
    </inertial>
    <visual>
      <origin rpy="0 0 0" xyz="0.001 0.014069 -0.261262"/>
      <geometry>
        <mesh filename="package://robotic_arm_description/meshes/link_2.stl" scale="0.001 0.001 0.001"/>
      </geometry>
      <material name="pa_12_nylon_pa_603cf_with_eos_p_3d_printers"/>
    </visual>
    <collision>
      <origin rpy="0 0 0" xyz="0.001 0.014069 -0.261262"/>
      <geometry>
        <mesh filename="package://robotic_arm_description/meshes/link_2.stl" scale="0.001 0.001 0.001"/>
      </geometry>
    </collision>
  </link>
  <link name="link_3">
    <visual>
      <origin rpy="0 0 0" xyz="0 0 -0.06"/>
      <geometry>
        <box size="0.01 0.01 0.12"/>
      </geometry>
    </visual>
  </link>
  <link name="tool_0">
</link>
  <joint name="virtual_joint" type="fixed">
    <origin rpy="0.0 0.0 0.0" xyz="0.0 0.0 0.0"/>
    <parent link="world"/>
    <child link="base_link"/>
  </joint>
  <joint name="rigid_1" type="fixed">
    <origin rpy="0 0 0" xyz="0.0 0.07 0.015"/>
    <parent link="base_link"/>
    <child link="base"/>
  </joint>
  <joint name="base_waist_joint" type="revolute">
    <origin rpy="0 0 0" xyz="-0.0 -0.07 0.086"/>
    <parent link="base"/>
    <child link="waist"/>
    <axis xyz="0.0 0.0 1.0"/>
    <dynamics damping="10.0" friction="2.0"/>
    <limit effort="100" lower="-3.14" upper="3.14" velocity="100"/>
  </joint>
  <joint name="waist_link1_joint" type="revolute">
    <origin rpy="0 0 0" xyz="-0.001 -0.014069 0.040262"/>
    <parent link="waist"/>
    <child link="link_1"/>
    <axis xyz="1.0 0.0 -0.0"/>
    <dynamics damping="10.0" friction="2.0"/>
    <limit effort="100" lower="-3.14" upper="3.14" velocity="100"/>
  </joint>
  <joint name="link1_link2_joint" type="revolute">
    <origin rpy="0 0 0" xyz="0.0 0.0 0.12"/>
    <parent link="link_1"/>
    <child link="link_2"/>
    <axis xyz="-1.0 0.0 -0.0"/>
    <dynamics damping="10.0" friction="2.0"/>
    <limit effort="100" lower="-3.14" upper="3.141593" velocity="100"/>
  </joint>
  <joint name="link2_link3_joint" type="revolute">
    <origin rpy="-1.57 0 0" xyz="0.002 -0.12 0.0"/>
    <parent link="link_2"/>
    <child link="link_3"/>
    <axis xyz="1.0 0.0 0.0"/>
    <dynamics damping="10.0" friction="2.0"/>
    <limit effort="100" lower="-3.14" upper="3.14" velocity="100"/>
  </joint>
  <joint name="tool_joint" type="fixed">
    <origin rpy="0 0 0" xyz="0 0 -0.12"/>
    <parent link="link_3"/>
    <child link="tool_0"/>
  </joint>
</robot>
